2019-06-03 13:06:16,125 |        fcr.MyLogging |           MainThread |      DEBUG | Created logger
2019-06-03 13:06:16,125 |     fcr.poppler_test |           MainThread |      DEBUG | Created logger
2019-06-03 13:06:16,159 |     fcr.poppler_test |           MainThread |      DEBUG | I    = C:\pdf_extractor\pdf_extractor\pdf_extractor.py:39
2019-06-03 13:06:16,159 |     fcr.poppler_test |           MainThread |      DEBUG |  F   = <function check_output at 0x000001E5F3E65730>
2019-06-03 13:06:16,161 |     fcr.poppler_test |           MainThread |      DEBUG |   P  = (['poppler-0.68.0\\bin\\pdftocairo.exe', '-png', '-f', '1', 'raw\\7Wonders-CardsList-EN.pdf'],) {}
2019-06-03 13:06:18,602 |     fcr.poppler_test |           MainThread |      ERROR | Something went wrong! Exception details:
Traceback (most recent call last):
  File "C:\pdf_extractor\pdf_extractor\pdf_extractor.py", line 39, in <module>
    subprocess.check_output([r'poppler-0.68.0\bin\pdftocairo.exe', '-png', '-f', '1',  r'raw\7Wonders-CardsList-EN.pdf'])
  File "C:\pdf_extractor\pdf_extractor\MyLogging.py", line 86, in wrapper
    RetVal_ = func(*args, **kwargs)
  File "C:\Users\romain.thibault\AppData\Local\Programs\Python\Python37\lib\subprocess.py", line 395, in check_output
    **kwargs).stdout
  File "C:\Users\romain.thibault\AppData\Local\Programs\Python\Python37\lib\subprocess.py", line 474, in run
    stdout, stderr = process.communicate(input, timeout=timeout)
  File "C:\Users\romain.thibault\AppData\Local\Programs\Python\Python37\lib\subprocess.py", line 926, in communicate
    stdout = self.stdout.read()
KeyboardInterrupt

2019-06-03 13:06:18,603 |     fcr.poppler_test |           MainThread |      DEBUG | END of __main__
