2019-06-03 12:21:02,431 |        fcr.MyLogging |           MainThread |      DEBUG | Created logger
2019-06-03 12:21:02,432 |     fcr.poppler_test |           MainThread |      DEBUG | Created logger
2019-06-03 12:21:02,459 |     fcr.poppler_test |           MainThread |      DEBUG | I    = C:\pdf_extractor\pdf_extractor\pdf_extractor.py:38
2019-06-03 12:21:02,460 |     fcr.poppler_test |           MainThread |      DEBUG |  F   = <function check_output at 0x000001BBA4135730>
2019-06-03 12:21:02,461 |     fcr.poppler_test |           MainThread |      DEBUG |   P  = (['poppler-0.68.0\\bin\\pdftocairo.exe', 'raw\\7Wonders-CardsList-EN.pdf', 'proc\\pdftocairo_out.png'],) {}
2019-06-03 12:21:02,520 |     fcr.poppler_test |           MainThread |      ERROR | Something went wrong! Exception details:
Traceback (most recent call last):
  File "C:\pdf_extractor\pdf_extractor\pdf_extractor.py", line 38, in <module>
    subprocess.check_output([r"poppler-0.68.0\bin\pdftocairo.exe", PdfSrcPath, r'proc\pdftocairo_out.png'])
  File "C:\pdf_extractor\pdf_extractor\MyLogging.py", line 86, in wrapper
    RetVal_ = func(*args, **kwargs)
  File "C:\Users\romain.thibault\AppData\Local\Programs\Python\Python37\lib\subprocess.py", line 395, in check_output
    **kwargs).stdout
  File "C:\Users\romain.thibault\AppData\Local\Programs\Python\Python37\lib\subprocess.py", line 487, in run
    output=stdout, stderr=stderr)
subprocess.CalledProcessError: Command '['poppler-0.68.0\\bin\\pdftocairo.exe', 'raw\\7Wonders-CardsList-EN.pdf', 'proc\\pdftocairo_out.png']' returned non-zero exit status 99.

2019-06-03 12:21:02,521 |     fcr.poppler_test |           MainThread |      DEBUG | END of __main__
