2019-06-03 12:32:16,534 |        fcr.MyLogging |           MainThread |      DEBUG | Created logger
2019-06-03 12:32:16,534 |     fcr.poppler_test |           MainThread |      DEBUG | Created logger
2019-06-03 12:32:16,562 |     fcr.poppler_test |           MainThread |      DEBUG | I    = C:\pdf_extractor\pdf_extractor\pdf_extractor.py:38
2019-06-03 12:32:16,563 |     fcr.poppler_test |           MainThread |      DEBUG |  F   = <function check_output at 0x0000028A29A65730>
2019-06-03 12:32:16,565 |     fcr.poppler_test |           MainThread |      DEBUG |   P  = (['poppler-0.68.0\\bin\\pdftocairo.exe', '-png', '-f 1', '-l 1', '-x 124', '-y 349', '-W 140', '-H 59', 'raw\\7Wonders-CardsList-EN.pdf'],) {}
2019-06-03 12:32:16,881 |     fcr.poppler_test |           MainThread |      ERROR | Something went wrong! Exception details:
Traceback (most recent call last):
  File "C:\pdf_extractor\pdf_extractor\pdf_extractor.py", line 38, in <module>
    subprocess.check_output([r"poppler-0.68.0\bin\pdftocairo.exe", '-png', '-f 1', '-l 1', '-x 124', '-y 349', '-W 140', '-H 59', PdfSrcPath])
  File "C:\pdf_extractor\pdf_extractor\MyLogging.py", line 86, in wrapper
    RetVal_ = func(*args, **kwargs)
  File "C:\Users\romain.thibault\AppData\Local\Programs\Python\Python37\lib\subprocess.py", line 395, in check_output
    **kwargs).stdout
  File "C:\Users\romain.thibault\AppData\Local\Programs\Python\Python37\lib\subprocess.py", line 487, in run
    output=stdout, stderr=stderr)
subprocess.CalledProcessError: Command '['poppler-0.68.0\\bin\\pdftocairo.exe', '-png', '-f 1', '-l 1', '-x 124', '-y 349', '-W 140', '-H 59', 'raw\\7Wonders-CardsList-EN.pdf']' returned non-zero exit status 99.

2019-06-03 12:32:16,882 |     fcr.poppler_test |           MainThread |      DEBUG | END of __main__
