2019-06-03 13:00:25,464 |        fcr.MyLogging |           MainThread |      DEBUG | Created logger
2019-06-03 13:00:25,465 |     fcr.poppler_test |           MainThread |      DEBUG | Created logger
2019-06-03 13:00:25,496 |     fcr.poppler_test |           MainThread |      DEBUG | I    = C:\pdf_extractor\pdf_extractor\pdf_extractor.py:38
2019-06-03 13:00:25,497 |     fcr.poppler_test |           MainThread |      DEBUG |  F   = <function check_output at 0x000001C20BD057B8>
2019-06-03 13:00:25,498 |     fcr.poppler_test |           MainThread |      DEBUG |   P  = (['poppler-0.68.0\\bin\\pdftocairo.exe -png -f 1 -l 1 -x 172 -y 484 -W 196 -H 83 raw\\7Wonders-CardsList-EN.pdf'],) {}
2019-06-03 13:00:25,500 |     fcr.poppler_test |           MainThread |      ERROR | Something went wrong! Exception details:
Traceback (most recent call last):
  File "C:\pdf_extractor\pdf_extractor\pdf_extractor.py", line 38, in <module>
    subprocess.check_output([r'poppler-0.68.0\bin\pdftocairo.exe -png -f 1 -l 1 -x 172 -y 484 -W 196 -H 83 raw\7Wonders-CardsList-EN.pdf'])
  File "C:\pdf_extractor\pdf_extractor\MyLogging.py", line 86, in wrapper
    RetVal_ = func(*args, **kwargs)
  File "C:\Users\romain.thibault\AppData\Local\Programs\Python\Python37\lib\subprocess.py", line 395, in check_output
    **kwargs).stdout
  File "C:\Users\romain.thibault\AppData\Local\Programs\Python\Python37\lib\subprocess.py", line 472, in run
    with Popen(*popenargs, **kwargs) as process:
  File "C:\Users\romain.thibault\AppData\Local\Programs\Python\Python37\lib\subprocess.py", line 775, in __init__
    restore_signals, start_new_session)
  File "C:\Users\romain.thibault\AppData\Local\Programs\Python\Python37\lib\subprocess.py", line 1178, in _execute_child
    startupinfo)
FileNotFoundError: [WinError 2] The system cannot find the file specified

2019-06-03 13:00:25,501 |     fcr.poppler_test |           MainThread |      DEBUG | END of __main__
