2019-06-03 11:36:01,198 |             fcr.Misc |           MainThread |      DEBUG | Created logger
2019-06-03 11:36:01,198 |     fcr.poppler_test |           MainThread |      DEBUG | Created logger
2019-06-03 11:36:01,206 |     fcr.poppler_test |           MainThread |      DEBUG | I    = C:\pdf_extractor\pdf_extractor\pdf_extractor.py:25
2019-06-03 11:36:01,206 |     fcr.poppler_test |           MainThread |      DEBUG |  F   = <function check_output at 0x000001EB0BBBDE18>
2019-06-03 11:36:01,207 |     fcr.poppler_test |           MainThread |      DEBUG |   P  = (['poppler-0.68.0\\bin\\pdftotext.exe', '-bbox', 'raw\\7Wonders-CardsList-EN.pdf', 'proc\\7Wonders-CardsList-EN.html'],) {}
2019-06-03 11:36:01,213 |     fcr.poppler_test |           MainThread |      ERROR | Something went wrong! Exception details:
Traceback (most recent call last):
  File "C:\pdf_extractor\pdf_extractor\pdf_extractor.py", line 25, in <module>
    subprocess.check_output([r"poppler-0.68.0\bin\pdftotext.exe", "-bbox", PdfSrcPath, HtmlDstPath])
  File "C:\pdf_extractor\pdf_extractor\Misc.py", line 122, in wrapper
    RetVal_ = func(*args, **kwargs)
  File "C:\Users\romain.thibault\AppData\Local\Programs\Python\Python37\lib\subprocess.py", line 395, in check_output
    **kwargs).stdout
  File "C:\Users\romain.thibault\AppData\Local\Programs\Python\Python37\lib\subprocess.py", line 472, in run
    with Popen(*popenargs, **kwargs) as process:
  File "C:\Users\romain.thibault\AppData\Local\Programs\Python\Python37\lib\subprocess.py", line 775, in __init__
    restore_signals, start_new_session)
  File "C:\Users\romain.thibault\AppData\Local\Programs\Python\Python37\lib\subprocess.py", line 1178, in _execute_child
    startupinfo)
FileNotFoundError: [WinError 2] The system cannot find the file specified

2019-06-03 11:36:01,213 |     fcr.poppler_test |           MainThread |      DEBUG | END of __main__
