2019-06-03 13:06:24,476 |        fcr.MyLogging |           MainThread |      DEBUG | Created logger
2019-06-03 13:06:24,477 |     fcr.poppler_test |           MainThread |      DEBUG | Created logger
2019-06-03 13:06:24,509 |     fcr.poppler_test |           MainThread |      DEBUG | I    = C:\pdf_extractor\pdf_extractor\pdf_extractor.py:39
2019-06-03 13:06:24,510 |     fcr.poppler_test |           MainThread |      DEBUG |  F   = <function check_output at 0x00000280E1035730>
2019-06-03 13:06:24,511 |     fcr.poppler_test |           MainThread |      DEBUG |   P  = (['poppler-0.68.0\\bin\\pdftocairo.exe', '-png', '-f 1', 'raw\\7Wonders-CardsList-EN.pdf'],) {}
2019-06-03 13:06:24,563 |     fcr.poppler_test |           MainThread |      ERROR | Something went wrong! Exception details:
Traceback (most recent call last):
  File "C:\pdf_extractor\pdf_extractor\pdf_extractor.py", line 39, in <module>
    subprocess.check_output([r'poppler-0.68.0\bin\pdftocairo.exe', '-png', '-f 1',  r'raw\7Wonders-CardsList-EN.pdf'])
  File "C:\pdf_extractor\pdf_extractor\MyLogging.py", line 86, in wrapper
    RetVal_ = func(*args, **kwargs)
  File "C:\Users\romain.thibault\AppData\Local\Programs\Python\Python37\lib\subprocess.py", line 395, in check_output
    **kwargs).stdout
  File "C:\Users\romain.thibault\AppData\Local\Programs\Python\Python37\lib\subprocess.py", line 487, in run
    output=stdout, stderr=stderr)
subprocess.CalledProcessError: Command '['poppler-0.68.0\\bin\\pdftocairo.exe', '-png', '-f 1', 'raw\\7Wonders-CardsList-EN.pdf']' returned non-zero exit status 1.

2019-06-03 13:06:24,563 |     fcr.poppler_test |           MainThread |      DEBUG | END of __main__
